test('this test is erroring', () => {
  throw new Error("can't catch me");
});
